2019-02-28 17:40:22,358 - public_methods.py[line:107] - INFO: 执行更新数据时报错，报错为:[Errno 11001] getaddrinfo failed
2019-02-28 17:40:22,358 - public_methods.py[line:107] - INFO: 执行更新数据时报错，报错为:[Errno 11001] getaddrinfo failed
2019-02-28 17:40:22,358 - public_methods.py[line:107] - INFO: 执行更新数据时报错，报错为:[Errno 11001] getaddrinfo failed
2019-02-28 17:40:22,358 - public_methods.py[line:107] - INFO: 执行更新数据时报错，报错为:[Errno 11001] getaddrinfo failed
